2023-03-27 13:36:38,281 INFO    MainThread:2058706 [internal.py:wandb_internal():88] W&B internal server running at pid: 2058706, started at: 2023-03-27 13:36:38.281022
2023-03-27 13:36:38,282 DEBUG   HandlerThread:2058706 [handler.py:handle_request():130] handle_request: check_version
2023-03-27 13:36:38,282 INFO    WriterThread:2058706 [datastore.py:open_for_write():77] open: /home/soheil/DRL-Bench/drl/testjax/wandb/run-20230327_133637-20t0fvre/run-20t0fvre.wandb
2023-03-27 13:36:38,283 DEBUG   SenderThread:2058706 [sender.py:send():185] send: header
2023-03-27 13:36:38,283 DEBUG   SenderThread:2058706 [sender.py:send_request():199] send_request: check_version
2023-03-27 13:36:38,314 DEBUG   SenderThread:2058706 [sender.py:send():185] send: run
2023-03-27 13:36:38,401 ERROR   SenderThread:2058706 [internal_api.py:execute():144] 404 response executing GraphQL.
2023-03-27 13:36:38,401 ERROR   SenderThread:2058706 [internal_api.py:execute():145] {"errors":[{"message":"entity drl-bench not found during upsertBucket","path":["upsertBucket"]}],"data":{"upsertBucket":null}}
2023-03-27 13:36:39,314 INFO    WriterThread:2058706 [datastore.py:close():281] close: /home/soheil/DRL-Bench/drl/testjax/wandb/run-20230327_133637-20t0fvre/run-20t0fvre.wandb
2023-03-27 13:36:39,315 INFO    HandlerThread:2058706 [handler.py:finish():731] shutting down handler
2023-03-27 13:36:39,315 ERROR   MainThread:2058706 [internal.py:wandb_internal():159] Thread SenderThread:
Traceback (most recent call last):
  File "/home/soheil/miniconda3/envs/bench/lib/python3.10/site-packages/wandb/sdk/lib/retry.py", line 102, in __call__
    result = self._call_fn(*args, **kwargs)
  File "/home/soheil/miniconda3/envs/bench/lib/python3.10/site-packages/wandb/sdk/internal/internal_api.py", line 147, in execute
    six.reraise(*sys.exc_info())
  File "/home/soheil/miniconda3/envs/bench/lib/python3.10/site-packages/six.py", line 719, in reraise
    raise value
  File "/home/soheil/miniconda3/envs/bench/lib/python3.10/site-packages/wandb/sdk/internal/internal_api.py", line 141, in execute
    return self.client.execute(*args, **kwargs)
  File "/home/soheil/miniconda3/envs/bench/lib/python3.10/site-packages/wandb/vendor/gql-0.2.0/gql/client.py", line 52, in execute
    result = self._get_result(document, *args, **kwargs)
  File "/home/soheil/miniconda3/envs/bench/lib/python3.10/site-packages/wandb/vendor/gql-0.2.0/gql/client.py", line 60, in _get_result
    return self.transport.execute(document, *args, **kwargs)
  File "/home/soheil/miniconda3/envs/bench/lib/python3.10/site-packages/wandb/vendor/gql-0.2.0/gql/transport/requests.py", line 39, in execute
    request.raise_for_status()
  File "/home/soheil/miniconda3/envs/bench/lib/python3.10/site-packages/requests/models.py", line 1021, in raise_for_status
    raise HTTPError(http_error_msg, response=self)
requests.exceptions.HTTPError: 404 Client Error: Not Found for url: https://api.wandb.ai/graphql

During handling of the above exception, another exception occurred:

Traceback (most recent call last):
  File "/home/soheil/miniconda3/envs/bench/lib/python3.10/site-packages/wandb/apis/normalize.py", line 24, in wrapper
    return func(*args, **kwargs)
  File "/home/soheil/miniconda3/envs/bench/lib/python3.10/site-packages/wandb/sdk/internal/internal_api.py", line 1270, in upsert_run
    response = self.gql(mutation, variable_values=variable_values, **kwargs)
  File "/home/soheil/miniconda3/envs/bench/lib/python3.10/site-packages/wandb/sdk/lib/retry.py", line 118, in __call__
    if not check_retry_fn(e):
  File "/home/soheil/miniconda3/envs/bench/lib/python3.10/site-packages/wandb/util.py", line 821, in no_retry_auth
    raise CommError("Permission denied, ask the project owner to grant you access")
wandb.errors.CommError: Permission denied, ask the project owner to grant you access

During handling of the above exception, another exception occurred:

Traceback (most recent call last):
  File "/home/soheil/miniconda3/envs/bench/lib/python3.10/site-packages/wandb/sdk/internal/internal_util.py", line 52, in run
    self._run()
  File "/home/soheil/miniconda3/envs/bench/lib/python3.10/site-packages/wandb/sdk/internal/internal_util.py", line 102, in _run
    self._process(record)
  File "/home/soheil/miniconda3/envs/bench/lib/python3.10/site-packages/wandb/sdk/internal/internal.py", line 292, in _process
    self._sm.send(record)
  File "/home/soheil/miniconda3/envs/bench/lib/python3.10/site-packages/wandb/sdk/internal/sender.py", line 187, in send
    send_handler(record)
  File "/home/soheil/miniconda3/envs/bench/lib/python3.10/site-packages/wandb/sdk/internal/sender.py", line 652, in send_run
    self._init_run(run, config_value_dict)
  File "/home/soheil/miniconda3/envs/bench/lib/python3.10/site-packages/wandb/sdk/internal/sender.py", line 673, in _init_run
    server_run, inserted = self._api.upsert_run(
  File "/home/soheil/miniconda3/envs/bench/lib/python3.10/site-packages/wandb/apis/normalize.py", line 62, in wrapper
    six.reraise(CommError, CommError(message, err), sys.exc_info()[2])
  File "/home/soheil/miniconda3/envs/bench/lib/python3.10/site-packages/six.py", line 718, in reraise
    raise value.with_traceback(tb)
  File "/home/soheil/miniconda3/envs/bench/lib/python3.10/site-packages/wandb/apis/normalize.py", line 24, in wrapper
    return func(*args, **kwargs)
  File "/home/soheil/miniconda3/envs/bench/lib/python3.10/site-packages/wandb/sdk/internal/internal_api.py", line 1270, in upsert_run
    response = self.gql(mutation, variable_values=variable_values, **kwargs)
  File "/home/soheil/miniconda3/envs/bench/lib/python3.10/site-packages/wandb/sdk/lib/retry.py", line 118, in __call__
    if not check_retry_fn(e):
  File "/home/soheil/miniconda3/envs/bench/lib/python3.10/site-packages/wandb/util.py", line 821, in no_retry_auth
    raise CommError("Permission denied, ask the project owner to grant you access")
wandb.errors.CommError: Permission denied, ask the project owner to grant you access
2023-03-27 13:36:41,331 INFO    MainThread:2058706 [internal.py:handle_exit():78] Internal process exited
